Workbook

Sheet Roteiro
B2: Questão | D2: Valor | E2: Peso % | F2: Sub-peso %
D3: 10
B5: 1 | C5: Pesquisa preliminar sobre o domínio e sistemas existentes | D5: =E5/100*$D$3 -> 1 | E5: 10
B6: 2 | C6: Pesquisa com usuários – Entrevistas | D6: =E6/100*$D$3 -> 2.9 | E6: 29 | F6: =SUM(E7,E13,E19) -> 100
B7: 2.1 | C7: Entrevista: Preparação | D7: =E7/100*$D$6 -> 1.16 | E7: 40 | F7: =SUM(E8:E12) -> 100
B8: 2.1.1 | C8: Papel e perfil dos entrevistados que serão recrutados | D8: =E8/100*$D$7 -> 0.348 | E8: 30
B9: 2.1.2 | C9: Modelo de Termo de Consentimento (TCLE) para as entrevistas | D9: =E9/100*$D$7 -> 0.058 | E9: 5
B10: 2.1.3 | C10: Roteiro preliminar de entrevista | D10: =E10/100*$D$7 -> 0.638 | E10: 55
B11: 2.1.3 | C11: Apresentação do roteiro da entrevista | D11: =E11/100*$D$7 -> 0.058 | E11: 5
B12: 2.1.4 | C12: Preparação para a condução da entrevista | D12: =E12/100*$D$7 -> 0.058 | E12: 5
B13: 2.2 | C13: Entrevista-piloto: condução e análise | D13: =E13/100*$D$6 -> 0.725 | E13: 25 | F13: =SUM(E14:E18) -> 100
B14: 2.2.1 | C14: TCLE assinado para a entrevista-piloto | D14: =E14/100*$D$13 -> 0.029 | E14: 4
B15: 2.2.2 | C15: “Transcrição” da entrevista-piloto | D15: =E15/100*$D$13 -> 0.174 | E15: 24
B16: 2.2.3 | C16: Análise da condução da entrevista-piloto | D16: =E16/100*$D$13 -> 0.174 | E16: 24
B17: 2.2.4 | C17: Análise do conteúdo da entrevista-piloto e do roteiro | D17: =E17/100*$D$13 -> 0.174 | E17: 24
B18: 2.2.5 | C18: Revisão do roteiro de entrevista | D18: =E18/100*$D$13 -> 0.174 | E18: 24
B19: 2.3 | C19: Entrevistas: condução e análise | D19: =E19/100*$D$6 -> 1.015 | E19: 35 | F19: =SUM(E20,E21,E22,E27) -> 100
B20: 2.3.1 | C20: Alocação de entrevistados por aluno | D20: =E20/100*$D$19 -> 0.0203 | E20: 2
B21: 2.3.2 | C21: Perfil dos entrevistados | D21: =E21/100*$D$19 -> 0.0609 | E21: 6
B22: 2.3.3 | C22: Entrevista com E01 – A1 – NomeDoAluno | D22: =E22/100*$D$19 -> 0.55825 | E22: 55 | F22: =SUM(E23:E26) -> 100
B23: 2.3.3.1 | C23: TCLE digitalizado | D23: =E23/100*$D$22 -> 0.02233 | E23: 4
B24: 2.3.3.2 | C24: Transcrição | D24: =E24/100*$D$22 -> 0.122815 | E24: 22
B25: 2.3.3.3 | C25: Análise individual da condução | D25: =E25/100*$D$22 -> 0.2065525 | E25: 37
B26: 2.3.3.4 | C26: Análise individual do conteúdo | D26: =E26/100*$D$22 -> 0.2065525 | E26: 37
B27: 2.3.4 | C27: Análise consolidada das entrevistas | D27: =E27/100*$D$19 -> 0.37555 | E27: 37
B28: 3 | C28: Pesquisa com usuários – Questionários | D28: =E28/100*$D$3 -> 2 | E28: 20 | F28: =SUM(E29,E34,E37,E38) -> 100
B29: 3.1 | C29: Preparação para o questionário | D29: =E29/100*$D$28 -> 0.8 | E29: 40 | F29: =SUM(E30:E33) -> 100
B30: 3.1.1 | C30: Estratégias de distribuição do questionário | D30: =E30/100*$D$29 -> 0.04 | E30: 5
B31: 3.1.2 | C31: Modelo de Termo de Consentimento (TCLE) para o questionário | D31: =E31/100*$D$29 -> 0.04 | E31: 5
B32: 3.1.3 | C32: Estrutura e conteúdo preliminar do questionário | D32: =E32/100*$D$29 -> 0.68 | E32: 85
B33: 3.1.3 | C33: Apresentação do questionário preliminar | D33: =E33/100*$D$29 -> 0.04 | E33: 5
B34: 3.2 | C34: Questionário-piloto | D34: =E34/100*$D$28 -> 0.38 | E34: 19 | F34: =SUM(E35:E36) -> 100
B35: 3.2.1 | C35: Análise do questionário-piloto | D35: =E35/100*$D$34 -> 0.19 | E35: 50
B36: 3.2.2 | C36: Revisão e consolidação do questionário | D36: =E36/100*$D$34 -> 0.19 | E36: 50
B37: 3.3 | C37: Divulgação e coleta de dados do questionário | D37: =E37/100*$D$28 -> 0.02 | E37: 1
B38: 3.4 | C38: Análise dos dados coletados | D38: =E38/100*$D$28 -> 0.8 | E38: 40
B39: 4 | C39: Papéis e Personas | D39: =E39/100*$D$3 -> 1.8 | E39: 18
B40: 5 | C40: Jornada de usuário | D40: =E40/100*$D$3 -> 1.8 | E40: 18
B41: 6 | C41: Apreciação do trabalho | D41: =E41/100*$D$3 -> 0.5 | E41: 5
B42: 7 | C42: Apresentação em sala aula | D42: =E42/100*$D$3 -> 0 | E42: 0
...

Sheet Grupo E
F2: Correção | M2: Ponto | T2: Texto feedback
D4: Valor da questão | F4: Eduardo Olinto (A1) | G4: Pedro Consales (A2) | H4: Guilherme Rosa (A3) | I4: Gustavo Valente (A4) | J4: Vitor Cid (A5) | K4: Pedro Ferreira Serpa (A6) | M4: =F4 -> Eduardo Olinto (A1) | N4: =G4 -> Pedro Consales (A2) | O4: =H4 -> Guilherme Rosa (A3) | P4: =I4 -> Gustavo Valente (A4) | Q4: =J4 -> Vitor Cid (A5) | R4: =K4 -> Pedro Ferreira Serpa (A6)
B5: 1 | C5: Pesquisa preliminar sobre o domínio e sistemas existentes | D5: =Roteiro!D5 -> 1 | F5: 0.8 | G5: 0 | H5: 0 | I5: 0 | J5: 0 | K5: 0 | M5: =$D5*F5 -> 0.8 | N5: =$D5*G5 -> 0 | O5: =$D5*H5 -> 0 | P5: =$D5*I5 -> 0 | Q5: =$D5*J5 -> 0 | R5: =$D5*K5 -> 0 | T5: =#REF! -> #REF!
B6: 2 | C6: Pesquisa com usuários – Entrevistas | D6: =Roteiro!D6 -> 2.9
B7: 2.1 | C7: Entrevista: Preparação | D7: =Roteiro!D7 -> 1.16
B8: 2.1.1 | C8: Papel e perfil dos entrevistados que serão recrutados | D8: =Roteiro!D8 -> 0.348 | F8: 0 | G8: 0 | H8: 0 | I8: 1 | J8: 0 | K8: 0 | M8: =$D8*F8 -> 0 | N8: =$D8*G8 -> 0 | O8: =$D8*H8 -> 0 | P8: =$D8*I8 -> 0.348 | Q8: =$D8*J8 -> 0 | R8: =$D8*K8 -> 0
B9: 2.1.2 | C9: Modelo de Termo de Consentimento (TCLE) para as entrevistas | D9: =Roteiro!D9 -> 0.058 | F9: 0.4 | G9: 0.4 | H9: 0.4 | I9: 0.4 | J9: 0.4 | K9: 0.4 | M9: =$D9*F9 -> 0.0232 | N9: =$D9*G9 -> 0.0232 | O9: =$D9*H9 -> 0.0232 | P9: =$D9*I9 -> 0.0232 | Q9: =$D9*J9 -> 0.0232 | R9: =$D9*K9 -> 0.0232
B10: 2.1.3 | C10: Roteiro preliminar de entrevista | D10: =Roteiro!D10 -> 0.638 | F10: 0.9 | G10: 0.9 | H10: 0 | I10: 0.9 | J10: 0 | K10: 0 | M10: =$D10*F10 -> 0.5742 | N10: =$D10*G10 -> 0.5742 | O10: =$D10*H10 -> 0 | P10: =$D10*I10 -> 0.5742 | Q10: =$D10*J10 -> 0 | R10: =$D10*K10 -> 0
B11: 2.1.3 | C11: Apresentação do roteiro da entrevista | D11: =Roteiro!D11 -> 0.058 | F11: 1 | G11: 1 | H11: 1 | I11: 1 | J11: 1 | K11: 1 | M11: =$D11*F11 -> 0.058 | N11: =$D11*G11 -> 0.058 | O11: =$D11*H11 -> 0.058 | P11: =$D11*I11 -> 0.058 | Q11: =$D11*J11 -> 0.058 | R11: =$D11*K11 -> 0.058
B12: 2.1.4 | C12: Preparação para a condução da entrevista | D12: =Roteiro!D12 -> 0.058 | F12: 0 | G12: 0 | H12: 0 | I12: 0.8 | J12: 0 | K12: 0 | M12: =$D12*F12 -> 0 | N12: =$D12*G12 -> 0 | O12: =$D12*H12 -> 0 | P12: =$D12*I12 -> 0.0464 | Q12: =$D12*J12 -> 0 | R12: =$D12*K12 -> 0 | T12: =#REF! -> #REF!
B13: 2.2 | C13: Entrevista-piloto: condução e análise | D13: =Roteiro!D13 -> 0.725
B14: 2.2.1 | C14: TCLE assinado para a entrevista-piloto | D14: =Roteiro!D14 -> 0.029 | F14: 0 | G14: 0 | H14: 0 | I14: 0 | J14: 0 | K14: 0 | M14: =$D14*F14 -> 0 | N14: =$D14*G14 -> 0 | O14: =$D14*H14 -> 0 | P14: =$D14*I14 -> 0 | Q14: =$D14*J14 -> 0 | R14: =$D14*K14 -> 0
B15: 2.2.2 | C15: “Transcrição” da entrevista-piloto | D15: =Roteiro!D15 -> 0.174 | F15: =(1/2)/2 -> 0.25 | G15: =(1/2)/2 -> 0.25 | H15: =(1/2)/2 -> 0.25 | I15: =(1/2)/2 -> 0.25 | J15: =(1/2)/2 -> 0.25 | K15: =(1/2)/2 -> 0.25 | M15: =$D15*F15 -> 0.0435 | N15: =$D15*G15 -> 0.0435 | O15: =$D15*H15 -> 0.0435 | P15: =$D15*I15 -> 0.0435 | Q15: =$D15*J15 -> 0.0435 | R15: =$D15*K15 -> 0.0435
B16: 2.2.3 | C16: Análise da condução da entrevista-piloto | D16: =Roteiro!D16 -> 0.174 | F16: 0 | G16: 0 | H16: 0 | I16: 0.2 | J16: 0 | K16: 0 | M16: =$D16*F16 -> 0 | N16: =$D16*G16 -> 0 | O16: =$D16*H16 -> 0 | P16: =$D16*I16 -> 0.0348 | Q16: =$D16*J16 -> 0 | R16: =$D16*K16 -> 0
B17: 2.2.4 | C17: Análise do conteúdo da entrevista-piloto e do roteiro | D17: =Roteiro!D17 -> 0.174 | F17: 0 | G17: 0 | H17: 0 | I17: 0.7 | J17: 0 | K17: 0 | M17: =$D17*F17 -> 0 | N17: =$D17*G17 -> 0 | O17: =$D17*H17 -> 0 | P17: =$D17*I17 -> 0.1218 | Q17: =$D17*J17 -> 0 | R17: =$D17*K17 -> 0
B18: 2.2.5 | C18: Revisão do roteiro de entrevista | D18: =Roteiro!D18 -> 0.174 | F18: 0 | G18: 0 | H18: 0 | I18: 0 | J18: 0 | K18: 0 | M18: =$D18*F18 -> 0 | N18: =$D18*G18 -> 0 | O18: =$D18*H18 -> 0 | P18: =$D18*I18 -> 0 | Q18: =$D18*J18 -> 0 | R18: =$D18*K18 -> 0
B19: 2.3 | C19: Entrevistas: condução e análise | D19: =Roteiro!D19 -> 1.015
B20: 2.3.1 | C20: Alocação de entrevistados por aluno | D20: =Roteiro!D20 -> 0.0203 | F20: 0 | G20: 1 | H20: 0 | I20: 1 | J20: 0 | K20: 0 | M20: =$D20*F20 -> 0 | N20: =$D20*G20 -> 0.0203 | O20: =$D20*H20 -> 0 | P20: =$D20*I20 -> 0.0203 | Q20: =$D20*J20 -> 0 | R20: =$D20*K20 -> 0
B21: 2.3.2 | C21: Perfil dos entrevistados | D21: =Roteiro!D21 -> 0.0609 | F21: 0 | G21: 0.5 | H21: 0 | I21: 0.5 | J21: 0 | K21: 0 | M21: =$D21*F21 -> 0 | N21: =$D21*G21 -> 0.03045 | O21: =$D21*H21 -> 0 | P21: =$D21*I21 -> 0.03045 | Q21: =$D21*J21 -> 0 | R21: =$D21*K21 -> 0
B22: 2.3.3 | C22: Entrevista com E01 – A1 – NomeDoAluno | D22: =Roteiro!D22 -> 0.55825
B23: 2.3.3.1 | C23: TCLE digitalizado | D23: =Roteiro!D23 -> 0.02233 | F23: 0 | G23: 0 | H23: 0 | I23: 0 | J23: 0 | K23: 0 | M23: =$D23*F23 -> 0 | N23: =$D23*G23 -> 0 | O23: =$D23*H23 -> 0 | P23: =$D23*I23 -> 0 | Q23: =$D23*J23 -> 0 | R23: =$D23*K23 -> 0
B24: 2.3.3.2 | C24: Transcrição | D24: =Roteiro!D24 -> 0.122815 | F24: 0 | G24: 0 | H24: 0 | I24: 0 | J24: 0 | K24: 0 | M24: =$D24*F24 -> 0 | N24: =$D24*G24 -> 0 | O24: =$D24*H24 -> 0 | P24: =$D24*I24 -> 0 | Q24: =$D24*J24 -> 0 | R24: =$D24*K24 -> 0
B25: 2.3.3.3 | C25: Análise individual da condução | D25: =Roteiro!D25 -> 0.2065525 | F25: 0 | G25: 0 | H25: 0 | I25: 0 | J25: 0 | K25: 0 | M25: =$D25*F25 -> 0 | N25: =$D25*G25 -> 0 | O25: =$D25*H25 -> 0 | P25: =$D25*I25 -> 0 | Q25: =$D25*J25 -> 0 | R25: =$D25*K25 -> 0
B26: 2.3.3.4 | C26: Análise individual do conteúdo | D26: =Roteiro!D26 -> 0.2065525 | F26: 0 | G26: 0 | H26: 0 | I26: 0 | J26: 0 | K26: 0 | M26: =$D26*F26 -> 0 | N26: =$D26*G26 -> 0 | O26: =$D26*H26 -> 0 | P26: =$D26*I26 -> 0 | Q26: =$D26*J26 -> 0 | R26: =$D26*K26 -> 0
B27: 2.3.4 | C27: Análise consolidada das entrevistas | D27: =Roteiro!D27 -> 0.37555 | F27: 0 | G27: 0 | H27: 0 | I27: 0 | J27: 0 | K27: 0 | M27: =$D27*F27 -> 0 | N27: =$D27*G27 -> 0 | O27: =$D27*H27 -> 0 | P27: =$D27*I27 -> 0 | Q27: =$D27*J27 -> 0 | R27: =$D27*K27 -> 0
B28: 3 | C28: Pesquisa com usuários – Questionários | D28: =Roteiro!D28 -> 2
B29: 3.1 | C29: Preparação para o questionário | D29: =Roteiro!D29 -> 0.8
B30: 3.1.1 | C30: Estratégias de distribuição do questionário | D30: =Roteiro!D30 -> 0.04 | F30: 0 | G30: 0.4 | H30: 0 | I30: 0 | J30: 0 | K30: 0 | M30: =$D30*F30 -> 0 | N30: =$D30*G30 -> 0.016 | O30: =$D30*H30 -> 0 | P30: =$D30*I30 -> 0 | Q30: =$D30*J30 -> 0 | R30: =$D30*K30 -> 0
B31: 3.1.2 | C31: Modelo de Termo de Consentimento (TCLE) para o questionário | D31: =Roteiro!D31 -> 0.04 | F31: 0 | G31: 0.8 | H31: 0 | I31: 0 | J31: 0 | K31: 0 | M31: =$D31*F31 -> 0 | N31: =$D31*G31 -> 0.032 | O31: =$D31*H31 -> 0 | P31: =$D31*I31 -> 0 | Q31: =$D31*J31 -> 0 | R31: =$D31*K31 -> 0
B32: 3.1.3 | C32: Estrutura e conteúdo preliminar do questionário | D32: =Roteiro!D32 -> 0.68 | F32: 0 | G32: 0 | H32: 0 | I32: 0 | J32: 0 | K32: 0 | M32: =$D32*F32 -> 0 | N32: =$D32*G32 -> 0 | O32: =$D32*H32 -> 0 | P32: =$D32*I32 -> 0 | Q32: =$D32*J32 -> 0 | R32: =$D32*K32 -> 0
B33: 3.1.3 | C33: Estrutura e conteúdo preliminar do questionário | D33: =Roteiro!D33 -> 0.04 | F33: 1 | G33: 1 | H33: 1 | I33: 1 | J33: 1 | K33: 0 | M33: =$D33*F33 -> 0.04 | N33: =$D33*G33 -> 0.04 | O33: =$D33*H33 -> 0.04 | P33: =$D33*I33 -> 0.04 | Q33: =$D33*J33 -> 0.04 | R33: =$D33*K33 -> 0
B34: 3.2 | C34: Questionário-piloto | D34: =Roteiro!D34 -> 0.38
B35: 3.2.1 | C35: Análise do questionário-piloto | D35: =Roteiro!D35 -> 0.19 | F35: 0 | G35: 0 | H35: 0 | I35: 0 | J35: 0 | K35: 0 | M35: =$D35*F35 -> 0 | N35: =$D35*G35 -> 0 | O35: =$D35*H35 -> 0 | P35: =$D35*I35 -> 0 | Q35: =$D35*J35 -> 0 | R35: =$D35*K35 -> 0
B36: 3.2.2 | C36: Revisão e consolidação do questionário | D36: =Roteiro!D36 -> 0.19 | F36: 0 | G36: 0 | H36: 0 | I36: 0 | J36: 0 | K36: 0 | M36: =$D36*F36 -> 0 | N36: =$D36*G36 -> 0 | O36: =$D36*H36 -> 0 | P36: =$D36*I36 -> 0 | Q36: =$D36*J36 -> 0 | R36: =$D36*K36 -> 0
B37: 3.3 | C37: Divulgação e coleta de dados do questionário | D37: =Roteiro!D37 -> 0.02 | F37: 0 | G37: 0 | H37: 0 | I37: 0 | J37: 0 | K37: 0 | M37: =$D37*F37 -> 0 | N37: =$D37*G37 -> 0 | O37: =$D37*H37 -> 0 | P37: =$D37*I37 -> 0 | Q37: =$D37*J37 -> 0 | R37: =$D37*K37 -> 0
B38: 3.4 | C38: Análise dos dados coletados | D38: =Roteiro!D38 -> 0.8 | F38: 0 | G38: 0.6 | H38: 0 | I38: 0.6 | J38: 0 | K38: 0 | M38: =$D38*F38 -> 0 | N38: =$D38*G38 -> 0.48 | O38: =$D38*H38 -> 0 | P38: =$D38*I38 -> 0.48 | Q38: =$D38*J38 -> 0 | R38: =$D38*K38 -> 0
B39: 4 | C39: Papéis e Personas | D39: =Roteiro!D39 -> 1.8 | F39: =(F55+F56)/2 -> 0 | G39: =(G55+G56)/2 -> 0 | H39: =(H55+H56)/2 -> 0 | I39: =(I55+I56)/2 -> 0 | J39: =(J55+J56)/2 -> 0.7 | K39: =(K55+K56)/2 -> 0 | M39: =$D39*F39 -> 0 | N39: =$D39*G39 -> 0 | O39: =$D39*H39 -> 0 | P39: =$D39*I39 -> 0 | Q39: =$D39*J39 -> 1.26 | R39: =$D39*K39 -> 0
B40: 5 | C40: Jornada de usuário | D40: =Roteiro!D40 -> 1.8 | F40: =(F58+F59)/2 -> 0 | G40: =(G58+G59)/2 -> 0 | H40: =(H58+H59)/2 -> 0 | I40: =(I58+I59)/2 -> 0 | J40: =(J58+J59)/2 -> 0 | K40: =(K58+K59)/2 -> 0 | M40: =$D40*F40 -> 0 | N40: =$D40*G40 -> 0 | O40: =$D40*H40 -> 0 | P40: =$D40*I40 -> 0 | Q40: =$D40*J40 -> 0 | R40: =$D40*K40 -> 0
B41: 6 | C41: Apreciação do trabalho | D41: =Roteiro!D41 -> 0.5 | F41: 1 | G41: 1 | H41: 1 | I41: 1 | J41: 1 | K41: 1 | M41: =$D41*F41 -> 0.5 | N41: =$D41*G41 -> 0.5 | O41: =$D41*H41 -> 0.5 | P41: =$D41*I41 -> 0.5 | Q41: =$D41*J41 -> 0.5 | R41: =$D41*K41 -> 0.5
B42: 7 | C42: Apresentação em sala aula | D42: =Roteiro!D42 -> 0 | M42: =$D42*F42 -> 0 | N42: =$D42*G42 -> 0 | O42: =$D42*H42 -> 0 | P42: =$D42*I42 -> 0 | Q42: =$D42*J42 -> 0 | R42: =$D42*K42 -> 0
...
